Workbook

Sheet Wage Detail Linked
A1: B&W PRODUCTIONS — WAGE DETAIL LINKED (master)
A2: Payroll week 2026-09-19 to 2026-09-25. One row per paid shift, including missed shifts from the previous payroll (real date shown). Edit only the yellow cells; Auditor Trail, Auditor Summary and Missed Shifts recalculate from this tab.
A4: Shift ID | B4: Employee | C4: Date | D4: Day | E4: Missed shift? | F4: Venue / Outlet | G4: Area | H4: Description | I4: Work type | J4: Start | K4: End | L4: Claimed hours | M4: Approved hours (system) | N4: Override hours (edit) | O4: Effective hours | P4: Amount (system) | Q4: Override amount (edit) | R4: Effective amount | S4: Rate used | T4: Breakdown (how the amount was worked out) | U4: Override reason (edit) | V4: Review # | W4: System note | X4: Review decision
A5: 9812 | B5: Bhekizitha Maphosa | C5: 2026-09-17 | D5: Thursday | E5: YES | F5: Botanical garden Pretoria | G5: Pretoria | H5: Break down | I5: Normal | J5: 06:00 | K5: 07:00 | L5: 1 | M5: 1 | O5: =IF(N5<>"",N5,M5) | P5: 95 | R5: =IF(Q5<>"",Q5,IF(N5<>"",IF(M5>0,ROUND(P5*N5/M5,2),0),P5)) | S5: 95 | T5: Venue/event: 1 h × R95 | W5: CLEAR: worked 07:00–16:00 that day (paid in payroll n/a); these hours are outside those times. | X5: No review needed
A6: 9811 | B6: Bhekizitha Maphosa | C6: 2026-09-17 | D6: Thursday | E6: YES | F6: FNB Stadium | G6: Johannesburg | H6: Setup fnb stadium Scorpion kings concert | I6: Normal | J6: 16:00 | K6: 18:00 | L6: 2 | M6: 2 | O6: =IF(N6<>"",N6,M6) | P6: 190 | R6: =IF(Q6<>"",Q6,IF(N6<>"",IF(M6>0,ROUND(P6*N6/M6,2),0),P6)) | S6: 95 | T6: Venue/event: 2 h × R95 | W6: CLEAR: worked 07:00–16:00 that day (paid in payroll n/a); these hours are outside those times. | X6: No review needed
A7: 9809 | B7: Bhekizitha Maphosa | C7: 2026-09-21 | D7: Monday | F7: FNB Stadium | G7: Fnb stadium | H7: Break down | I7: Normal | J7: 07:00 | K7: 16:00 | L7: 9 | M7: 9 | O7: =IF(N7<>"",N7,M7) | P7: 855 | R7: =IF(Q7<>"",Q7,IF(N7<>"",IF(M7>0,ROUND(P7*N7/M7,2),0),P7)) | S7: 95 | T7: Venue/event: 9 h × R95
A8: 9808 | B8: Bhekizitha Maphosa | C8: 2026-09-22 | D8: Tuesday | F8: Warehouse loading | G8: Henley on Klip, Meyerton | H8: Loading and cleaning | I8: Normal | J8: 07:00 | K8: 16:00 | L8: 9 | M8: 9 | O8: =IF(N8<>"",N8,M8) | P8: 690.63 | R8: =IF(Q8<>"",Q8,IF(N8<>"",IF(M8>0,ROUND(P8*N8/M8,2),0),P8)) | S8: 81.25 | T8: Warehouse: 9 h − 0.5 h staff meeting 07:00–07:30 (unpaid, R40,63) = 8.5 h × R81,25 | V8: #10027
A9: 9807 | B9: Bhekizitha Maphosa | C9: 2026-09-23 | D9: Wednesday | F9: Warehouse | G9: Henley on Klip, Meyerton | H9: Loading and cleaning | I9: Normal | J9: 07:00 | K9: 16:00 | L9: 9 | M9: 9 | O9: =IF(N9<>"",N9,M9) | P9: 690.63 | R9: =IF(Q9<>"",Q9,IF(N9<>"",IF(M9>0,ROUND(P9*N9/M9,2),0),P9)) | S9: 81.25 | T9: Warehouse: 9 h − 0.5 h staff meeting 07:00–07:30 (unpaid, R40,63) = 8.5 h × R81,25 | V9: #10025
A10: 9806 | B10: Bhekizitha Maphosa | C10: 2026-09-24 | D10: Thursday | F10: Warehouse | G10: Henley on Klip, Meyerton | H10: Loading and cleaning | I10: Warehouse Team | J10: 07:00 | K10: 15:00 | L10: 8 | M10: 8 | O10: =IF(N10<>"",N10,M10) | P10: 1218.75 | R10: =IF(Q10<>"",Q10,IF(N10<>"",IF(M10>0,ROUND(P10*N10/M10,2),0),P10)) | S10: 162.5 | T10: OWNER CORRECTION: Owner 23 Sep: Heritage Day — warehouse, hours set to 07:00–15:00 (no set-ups). 7.5 h × R162,50 = R1218.75 | V10: #10023 | W10: #10137 Public holiday (Heritage Day) — owner to approve or decline: PUBLIC HOLIDAY — Heritage Day (24 Sep 2026): Bhekizitha Maphosa worked 07:00–16:00. Held for owner approval. | X10: #10137 DECIDED 7.50 h by Bernie Burness 2026-09-23 10:28: Public holiday (Heritage Day) approved by Bernie Burness 23 Sep — hours set to 07:00–15:00 (no set-ups): Warehouse public holiday (Heritage Day), owner set hours 07:00–15:00: 8.0 h − 0.5 h staff meeting 07:00–07:30 (unpaid) = 7.5 h × R162,50 (R81,25 × 2) = R1218.75
A11: 9805 | B11: Bhekizitha Maphosa | C11: 2026-09-25 | D11: Friday | F11: The Capital Sandton and Bonitical Emmarentia | G11: Johannesburg | H11: Setup | I11: Normal | J11: 07:00 | K11: 16:00 | L11: 9 | M11: 9 | O11: =IF(N11<>"",N11,M11) | P11: 855 | R11: =IF(Q11<>"",Q11,IF(N11<>"",IF(M11>0,ROUND(P11*N11/M11,2),0),P11)) | S11: 95 | T11: Venue/event: 9 h × R95
A12: 9788 | B12: Daniel Motaung | C12: 2026-09-21 | D12: Monday | F12: FNB Stadium | G12: Johannesburg | H12: Breakdown | I12: Normal | J12: 07:00 | K12: 16:00 | L12: 9 | M12: 9 | O12: =IF(N12<>"",N12,M12) | P12: 855 | R12: =IF(Q12<>"",Q12,IF(N12<>"",IF(M12>0,ROUND(P12*N12/M12,2),0),P12)) | S12: 95 | T12: Venue/event: 9 h × R95
A13: 9787 | B13: Daniel Motaung | C13: 2026-09-22 | D13: Tuesday | F13: Warehouse loading | G13: Henley on Klip | H13: Warehouse | I13: Normal | J13: 07:00 | K13: 16:00 | L13: 9 | M13: 9 | O13: =IF(N13<>"",N13,M13) | P13: 690.63 | R13: =IF(Q13<>"",Q13,IF(N13<>"",IF(M13>0,ROUND(P13*N13/M13,2),0),P13)) | S13: 81.25 | T13: Warehouse: 9 h − 0.5 h staff meeting 07:00–07:30 (unpaid, R40,63) = 8.5 h × R81,25 | V13: #9990
A14: 9786 | B14: Daniel Motaung | C14: 2026-09-23 | D14: Wednesday | F14: Set up vaal Boating | G14: Vandrebilpark | H14: Set Up | I14: Normal | J14: 07:00 | K14: 16:00 | L14: 9 | M14: 9 | O14: =IF(N14<>"",N14,M14) | P14: 855 | R14: =IF(Q14<>"",Q14,IF(N14<>"",IF(M14>0,ROUND(P14*N14/M14,2),0),P14)) | S14: 95 | T14: Venue/event: 9 h × R95
A15: 9785 | B15: Daniel Motaung | C15: 2026-09-24 | D15: Thursday | F15: Warehouse | G15: Henley on Klip | H15: Warehouse | I15: Warehouse Team | J15: 07:00 | K15: 15:00 | L15: 8 | M15: 8 | O15: =IF(N15<>"",N15,M15) | P15: 1218.75 | R15: =IF(Q15<>"",Q15,IF(N15<>"",IF(M15>0,ROUND(P15*N15/M15,2),0),P15)) | S15: 162.5 | T15: OWNER CORRECTION: Owner 23 Sep: Heritage Day — warehouse, hours set to 07:00–15:00 (no set-ups). 7.5 h × R162,50 = R1218.75 | V15: #9987 | W15: #10138 Public holiday (Heritage Day) — owner to approve or decline: PUBLIC HOLIDAY — Heritage Day (24 Sep 2026): Daniel Motaung worked 07:00–16:00. Held for owner approval. | X15: #10138 DECIDED 7.50 h by Bernie Burness 2026-09-23 10:28: Public holiday (Heritage Day) approved by Bernie Burness 23 Sep — hours set to 07:00–15:00 (no set-ups): Warehouse public holiday (Heritage Day), owner set hours 07:00–15:00: 8.0 h − 0.5 h staff meeting 07:00–07:30 (unpaid) = 7.5 h × R162,50 (R81,25 × 2) = R1218.75
A16: 9784 | B16: Daniel Motaung | C16: 2026-09-25 | D16: Friday | F16: Vaal Boating | G16: Vandrebilpark | H16: Breakdown | I16: Normal | J16: 07:00 | K16: 16:00 | L16: 9 | M16: 9 | O16: =IF(N16<>"",N16,M16) | P16: 855 | R16: =IF(Q16<>"",Q16,IF(N16<>"",IF(M16>0,ROUND(P16*N16/M16,2),0),P16)) | S16: 95 | T16: Venue/event: 9 h × R95
A17: 9822 | B17: Erence Mngomezulu | C17: 2026-09-16 | D17: Wednesday | E17: YES | F17: Parys golf & country Estate | G17: Parys | H17: Setup | I17: Normal | J17: 16:00 | K17: 18:00 | L17: 2 | M17: 2 | O17: =IF(N17<>"",N17,M17) | P17: 190 | R17: =IF(Q17<>"",Q17,IF(N17<>"",IF(M17>0,ROUND(P17*N17/M17,2),0),P17)) | S17: 95 | T17: Venue/event: 2 h × R95 | W17: CLEAR: worked 07:00–16:00 that day (paid in payroll n/a); these hours are outside those times. | X17: No review needed
A18: 9823 | B18: Erence Mngomezulu | C18: 2026-09-17 | D18: Thursday | E18: YES | F18: Parys golf & country Estate | G18: Parys | H18: Setup | I18: Normal | J18: 06:00 | K18: 07:00 | L18: 1 | M18: 1 | O18: =IF(N18<>"",N18,M18) | P18: 95 | R18: =IF(Q18<>"",Q18,IF(N18<>"",IF(M18>0,ROUND(P18*N18/M18,2),0),P18)) | S18: 95 | T18: Venue/event: 1 h × R95 | W18: CLEAR: worked 07:00–16:00 that day (paid in payroll n/a); these hours are outside those times. | X18: No review needed
A19: 9824 | B19: Erence Mngomezulu | C19: 2026-09-17 | D19: Thursday | E19: YES | F19: Parys golf & country Estate | G19: Parys | H19: Strike down | I19: Normal | J19: 16:00 | K19: 20:00 | L19: 4 | M19: 4 | O19: =IF(N19<>"",N19,M19) | P19: 380 | R19: =IF(Q19<>"",Q19,IF(N19<>"",IF(M19>0,ROUND(P19*N19/M19,2),0),P19)) | S19: 95 | T19: Venue/event: 4 h × R95 | W19: CLEAR: worked 07:00–16:00 that day (paid in payroll n/a); these hours are outside those times. | X19: No review needed
A20: 9825 | B20: Erence Mngomezulu | C20: 2026-09-21 | D20: Monday | F20: FNB Stadium | G20: Johannesburg | H20: Strike down | I20: Normal | J20: 07:00 | K20: 16:00 | L20: 9 | M20: 9 | O20: =IF(N20<>"",N20,M20) | P20: 855 | R20: =IF(Q20<>"",Q20,IF(N20<>"",IF(M20>0,ROUND(P20*N20/M20,2),0),P20)) | S20: 95 | T20: Venue/event: 9 h × R95
A21: 9826 | B21: Erence Mngomezulu | C21: 2026-09-22 | D21: Tuesday | F21: Warehouse | G21: Meyerton | H21: Loading/offloading/cleaning and packing | I21: Normal | J21: 07:00 | K21: 16:00 | L21: 9 | M21: 9 | O21: =IF(N21<>"",N21,M21) | P21: 690.63 | R21: =IF(Q21<>"",Q21,IF(N21<>"",IF(M21>0,ROUND(P21*N21/M21,2),0),P21)) | S21: 81.25 | T21: Warehouse: 9 h − 0.5 h staff meeting 07:00–07:30 (unpaid, R40,63) = 8.5 h × R81,25 | V21: #10048
A22: 9827 | B22: Erence Mngomezulu | C22: 2026-09-23 | D22: Wednesday | F22: Warehouse | G22: Meyerton | H22: Loading/offloading/cleaning and packing | I22: Normal | J22: 07:00 | K22: 16:00 | L22: 9 | M22: 9 | O22: =IF(N22<>"",N22,M22) | P22: 690.63 | R22: =IF(Q22<>"",Q22,IF(N22<>"",IF(M22>0,ROUND(P22*N22/M22,2),0),P22)) | S22: 81.25 | T22: Warehouse: 9 h − 0.5 h staff meeting 07:00–07:30 (unpaid, R40,63) = 8.5 h × R81,25 | V22: #10050
A23: 9829 | B23: Erence Mngomezulu | C23: 2026-09-24 | D23: Thursday | F23: Warehouse | G23: Meyerton | H23: Loading/offloading/cleaning and packing | I23: Warehouse Team | J23: 07:00 | K23: 15:00 | L23: 8 | M23: 8 | O23: =IF(N23<>"",N23,M23) | P23: 1218.75 | R23: =IF(Q23<>"",Q23,IF(N23<>"",IF(M23>0,ROUND(P23*N23/M23,2),0),P23)) | S23: 162.5 | T23: OWNER CORRECTION: Owner 23 Sep: Heritage Day — warehouse, hours set to 07:00–15:00 (no set-ups). 7.5 h × R162,50 = R1218.75 | V23: #10053 | W23: #10139 Public holiday (Heritage Day) — owner to approve or decline: PUBLIC HOLIDAY — Heritage Day (24 Sep 2026): Erence Mngomezulu worked 07:00–16:00. Held for owner approval. | X23: #10139 DECIDED 7.50 h by Bernie Burness 2026-09-23 10:28: Public holiday (Heritage Day) approved by Bernie Burness 23 Sep — hours set to 07:00–15:00 (no set-ups): Warehouse public holiday (Heritage Day), owner set hours 07:00–15:00: 8.0 h − 0.5 h staff meeting 07:00–07:30 (unpaid) = 7.5 h × R162,50 (R81,25 × 2) = R1218.75
A24: 9828 | B24: Erence Mngomezulu | C24: 2026-09-25 | D24: Friday | F24: Pretoria country club | G24: Pretoria | H24: Setup/standby | I24: Normal | J24: 07:00 | K24: 16:00 | L24: 9 | M24: 9 | O24: =IF(N24<>"",N24,M24) | P24: 855 | R24: =IF(Q24<>"",Q24,IF(N24<>"",IF(M24>0,ROUND(P24*N24/M24,2),0),P24)) | S24: 95 | T24: Venue/event: 9 h × R95
A25: 9801 | B25: Erick Mpho Molefe | C25: 2026-09-17 | D25: Thursday | E25: YES | F25: FNB Stadium | G25: Johannesburg | H25: Setup FNB Stadium Scorpion Kings concert (extra hours after Clarens 07–16) | I25: Normal | J25: 16:00 | K25: 18:00 | L25: 2 | M25: 2 | O25: =IF(N25<>"",N25,M25) | P25: 190 | R25: =IF(Q25<>"",Q25,IF(N25<>"",IF(M25>0,ROUND(P25*N25/M25,2),0),P25)) | S25: 95 | T25: OWNER CORRECTION: Owner 23 Sep: worker entered this as Mon 21 Sep FNB strike down 07–16 — it was Thu 17 Sep 16:00–18:00 FNB Stadium (same as Bhekizitha #9811). 2 h × R95 = R190 | W25: CLEAR: worked 07:00–16:00 that day (paid in payroll n/a); these hours are outside those times. | X25: No review needed
A26: 9859 | B26: Erick Mpho Molefe | C26: 2026-09-21 | D26: Monday | F26: Warehouse | G26: Henley | H26: Loading (office-entered: worker put FNB on this date by mistake) | I26: Warehouse Team | J26: 07:00 | K26: 16:00 | L26: 9 | M26: 9 | O26: =IF(N26<>"",N26,M26) | P26: 690.63 | R26: =IF(Q26<>"",Q26,IF(N26<>"",IF(M26>0,ROUND(P26*N26/M26,2),0),P26)) | S26: 81.25 | T26: OWNER CORRECTION: Owner 23 Sep: Erick was in the warehouse Mon 21 Sep; his FNB entry on this date was really Thu 17 Sep 16–18. 9 h − 0.5 h meeting = 8.5 h × R81,25 = R690,63
A27: 9800 | B27: Erick Mpho Molefe | C27: 2026-09-22 | D27: Tuesday | F27: warehouse | G27: henley | H27: loading | I27: Normal | J27: 07:00 | K27: 16:00 | L27: 9 | M27: 9 | O27: =IF(N27<>"",N27,M27) | P27: 690.63 | R27: =IF(Q27<>"",Q27,IF(N27<>"",IF(M27>0,ROUND(P27*N27/M27,2),0),P27)) | S27: 81.25 | T27: Warehouse: 9 h − 0.5 h staff meeting 07:00–07:30 (unpaid, R40,63) = 8.5 h × R81,25 | V27: #10015
A28: 9799 | B28: Erick Mpho Molefe | C28: 2026-09-23 | D28: Wednesday | F28: wharehouse | G28: henley | H28: loading | I28: Normal | J28: 07:00 | K28: 16:00 | L28: 9 | M28: 9 | O28: =IF(N28<>"",N28,M28) | P28: 690.63 | R28: =IF(Q28<>"",Q28,IF(N28<>"",IF(M28>0,ROUND(P28*N28/M28,2),0),P28)) | S28: 81.25 | T28: OWNER CORRECTION: Warehouse (owner 23 Sep): 8.5 h × R81,25 = R690,63
A29: 9798 | B29: Erick Mpho Molefe | C29: 2026-09-24 | D29: Thursday | F29: wharehouse | G29: Henley | H29: loading | I29: Warehouse Team | J29: 07:00 | K29: 15:00 | L29: 8 | M29: 8 | O29: =IF(N29<>"",N29,M29) | P29: 1218.75 | R29: =IF(Q29<>"",Q29,IF(N29<>"",IF(M29>0,ROUND(P29*N29/M29,2),0),P29)) | S29: 162.5 | T29: OWNER CORRECTION: Owner 23 Sep: Heritage Day — warehouse, hours set to 07:00–15:00 (no set-ups). 7.5 h × R162,50 = R1218.75 | W29: #10010 Public holiday (Heritage Day) — owner to approve or decline: PUBLIC HOLIDAY — OWNER APPROVAL NEEDED: Erick Mpho Molefe worked 07:00–16:00 on 2026-09-24 (Heritage Day) at wharehouse (Normal). Public-holiday work is not paid automatically. Recommended: Venue/event public holiday (Heritage Day): 9 h × R190 (R95 × 2) = R1 710,00. R0 is paid until the owner approves or declines. | X29: #10010 DECIDED 7.50 h by Bernie Burness 2026-09-23 10:29: Public holiday (Heritage Day) approved by Bernie Burness 23 Sep — hours set to 07:00–15:00 (no set-ups): Warehouse public holiday (Heritage Day), owner set hours 07:00–15:00: 8.0 h − 0.5 h staff meeting 07:00–07:30 (unpaid) = 7.5 h × R162,50 (R81,25 × 2) = R1218.75
A30: 9797 | B30: Erick Mpho Molefe | C30: 2026-09-25 | D30: Friday | F30: Botanical | G30: johannessburg | H30: set up | I30: Normal | J30: 07:00 | K30: 16:00 | L30: 9 | M30: 9 | O30: =IF(N30<>"",N30,M30) | P30: 855 | R30: =IF(Q30<>"",Q30,IF(N30<>"",IF(M30>0,ROUND(P30*N30/M30,2),0),P30)) | S30: 95 | T30: Venue/event: 9 h × R95
A31: 9789 | B31: Givemore Chifetete Kuziwa | C31: 2026-09-17 | D31: Thursday | E31: YES | F31: Warehouse | G31: Pretoria and fnb | H31: Strike down and set up | I31: Warehouse Team | J31: 06:00 | K31: 18:00 | L31: 12 | M31: 12 | O31: =IF(N31<>"",N31,M31) | P31: 640 | R31: =IF(Q31<>"",Q31,IF(N31<>"",IF(M31>0,ROUND(P31*N31/M31,2),0),P31)) | S31: 95 | T31: DIFFERENCE ONLY (Venue R95/h chosen by Bernie Burness, #10073): Paid last week 08:00–16:00 House/Garden 8.00 h × R62,50 = R500,00 (shift #9705, payroll earlier); 06:00–18:00 at a venue = R1 140,00 (R95,00/h); less the House/Garden already paid R500,00; TO PAY THIS WEEK R640,00 | W31: OVERLAP: already paid 08:00–16:00 (Garden, R500,00, payroll n/a) on this day. | #10073 Warehouse claimed — but area says “Pretoria and fnb”: WAREHOUSE CLAIMED BUT AREA SAYS “Pretoria and fnb”: Givemore Chifetete Kuziwa selected Warehouse Team at “Warehouse” for 12.00 h on Thu 17 Sep 2026, but wrote the area as “Pretoria and fnb” — that is a venue, not the warehouse. Other workers were at Botanical garden Pretoria that day. If he was at “Pretoria and fnb”, he is due the venue rate (R95/h); if he was really in the warehouse, R81,25/h. Choose below. | X31: #10073 DECIDED by Bernie Burness 2026-09-23 08:58: Event/Venue rate chosen — shift #9789 R934,38 → R640,00 (Venue/event: 12 h × R95 → DIFFERENCE ONLY: Paid last week 08:00–16:00 House/Garden 8.00 h × R62,50 = R500,00 (shift #9705, payroll earlier); 06:00–18:00 at a venue = R1 140,00 (R95,00/h); less the House/Garden already paid R500,00; TO PAY THIS WEEK R640,00)
A32: 9790 | B32: Givemore Chifetete Kuziwa | C32: 2026-09-19 | D32: Saturday | F32: Garden | G32: Henley on klip | H32: Cleaning | I32: House/Garden | J32: 08:00 | K32: 14:00 | L32: 6 | M32: 6 | O32: =IF(N32<>"",N32,M32) | P32: 375 | R32: =IF(Q32<>"",Q32,IF(N32<>"",IF(M32>0,ROUND(P32*N32/M32,2),0),P32)) | S32: 62.5 | T32: Gardener House work: 6 h × R62,50
A33: 9791 | B33: Givemore Chifetete Kuziwa | C33: 2026-09-21 | D33: Monday | F33: Garden | G33: Henley on klip | H33: Cleaning | I33: House/Garden | J33: 08:00 | K33: 16:00 | L33: 8 | M33: 8 | O33: =IF(N33<>"",N33,M33) | P33: 500 | R33: =IF(Q33<>"",Q33,IF(N33<>"",IF(M33>0,ROUND(P33*N33/M33,2),0),P33)) | S33: 62.5 | T33: Gardener House work: 8 h × R62,50
A34: 9792 | B34: Givemore Chifetete Kuziwa | C34: 2026-09-22 | D34: Tuesday | F34: Garden | G34: Henley on klip | H34: Cleaning | I34: House/Garden | J34: 08:00 | K34: 16:00 | L34: 8 | M34: 8 | O34: =IF(N34<>"",N34,M34) | P34: 500 | R34: =IF(Q34<>"",Q34,IF(N34<>"",IF(M34>0,ROUND(P34*N34/M34,2),0),P34)) | S34: 62.5 | T34: Gardener House work: 8 h × R62,50
A35: 9793 | B35: Givemore Chifetete Kuziwa | C35: 2026-09-23 | D35: Wednesday | F35: Garden | G35: Henley on klip | H35: Cleaning | I35: House/Garden | J35: 08:00 | K35: 16:00 | L35: 8 | M35: 8 | O35: =IF(N35<>"",N35,M35) | P35: 500 | R35: =IF(Q35<>"",Q35,IF(N35<>"",IF(M35>0,ROUND(P35*N35/M35,2),0),P35)) | S35: 62.5 | T35: Gardener House work: 8 h × R62,50
A36: 9794 | B36: Givemore Chifetete Kuziwa | C36: 2026-09-24 | D36: Thursday | F36: Garden | G36: Henley on klip | H36: Cleaning | I36: House/Garden | J36: 08:00 | K36: 15:00 | L36: 7 | M36: 7 | O36: =IF(N36<>"",N36,M36) | P36: 875 | R36: =IF(Q36<>"",Q36,IF(N36<>"",IF(M36>0,ROUND(P36*N36/M36,2),0),P36)) | S36: 125 | T36: OWNER CORRECTION: Owner 23 Sep: Heritage Day — gardener hours set to 08:00–15:00; 7 h × R62,50 × 2 = R875 | W36: #10140 Public holiday (Heritage Day) — Givemore — approved R1 000,00 — CHECK HOURS NEXT WEEK: PUBLIC HOLIDAY — Heritage Day: Givemore (gardener) claimed 08:00–16:00. Owner: double the day = R1 000. VERIFY NEXT WEEK whether he actually worked 8 h or 4 h. | X36: #10140 DECIDED 7.00 h by Bernie Burness 2026-09-23 10:31: Public holiday (Heritage Day) approved by Bernie Burness 23 Sep — gardener, hours set to 08:00–15:00: 7 h × R62,50 × 2 = R875,00. CHECK NEXT WEEK what time he really worked until.
A37: 9795 | B37: Givemore Chifetete Kuziwa | C37: 2026-09-25 | D37: Friday | F37: Garden | G37: Henley on klip | H37: Cleaning | I37: House/Garden | J37: 08:00 | K37: 16:00 | L37: 8 | M37: 8 | O37: =IF(N37<>"",N37,M37) | P37: 500 | R37: =IF(Q37<>"",Q37,IF(N37<>"",IF(M37>0,ROUND(P37*N37/M37,2),0),P37)) | S37: 62.5 | T37: Gardener House work: 8 h × R62,50
A38: 9850 | B38: Isaac Mbele | C38: 2026-09-21 | D38: Monday | F38: Warehouse | G38: Randvaal, Gauteng, South Africa | H38: Off Loading | I38: Normal | J38: 07:00 | K38: 16:00 | L38: 9 | M38: 9 | O38: =IF(N38<>"",N38,M38) | P38: 690.63 | R38: =IF(Q38<>"",Q38,IF(N38<>"",IF(M38>0,ROUND(P38*N38/M38,2),0),P38)) | S38: 81.25 | T38: Warehouse: 9 h − 0.5 h staff meeting 07:00–07:30 (unpaid, R40,63) = 8.5 h × R81,25 | V38: #10104
A39: 9851 | B39: Isaac Mbele | C39: 2026-09-22 | D39: Tuesday | F39: Warehouse | G39: Randvaal, Gauteng, South Africa | H39: Loading | I39: Normal | J39: 07:00 | K39: 16:00 | L39: 9 | M39: 9 | O39: =IF(N39<>"",N39,M39) | P39: 690.63 | R39: =IF(Q39<>"",Q39,IF(N39<>"",IF(M39>0,ROUND(P39*N39/M39,2),0),P39)) | S39: 81.25 | T39: Warehouse: 9 h − 0.5 h staff meeting 07:00–07:30 (unpaid, R40,63) = 8.5 h × R81,25 | V39: #10106
A40: 9854 | B40: Isaac Mbele | C40: 2026-09-23 | D40: Wednesday | F40: Warehouse | G40: Randvaal, Gauteng, South Africa | H40: Loading | I40: Normal | J40: 07:00 | K40: 16:00 | L40: 9 | M40: 9 | O40: =IF(N40<>"",N40,M40) | P40: 690.63 | R40: =IF(Q40<>"",Q40,IF(N40<>"",IF(M40>0,ROUND(P40*N40/M40,2),0),P40)) | S40: 81.25 | T40: Warehouse: 9 h − 0.5 h staff meeting 07:00–07:30 (unpaid, R40,63) = 8.5 h × R81,25 | V40: #10118
A41: 9856 | B41: Isaac Mbele | C41: 2026-09-24 | D41: Thursday | F41: Warehouse | G41: Randvaal, Gauteng, South Africa | H41: Loading | I41: Warehouse Team | J41: 07:00 | K41: 15:00 | L41: 8 | M41: 8 | O41: =IF(N41<>"",N41,M41) | P41: 1218.75 | R41: =IF(Q41<>"",Q41,IF(N41<>"",IF(M41>0,ROUND(P41*N41/M41,2),0),P41)) | S41: 162.5 | T41: OWNER CORRECTION: Owner 23 Sep: Heritage Day — warehouse, hours set to 07:00–15:00 (no set-ups). 7.5 h × R162,50 = R1218.75 | V41: #10125 | W41: #10141 Public holiday (Heritage Day) — owner to approve or decline: PUBLIC HOLIDAY — Heritage Day (24 Sep 2026): Isaac Mbele worked 07:00–15:00. Held for owner approval. | X41: #10141 DECIDED 7.50 h by Bernie Burness 2026-09-23 10:32: Public holiday (Heritage Day) approved by Bernie Burness 23 Sep — hours set to 07:00–15:00 (no set-ups): Warehouse public holiday (Heritage Day), owner set hours 07:00–15:00: 8.0 h − 0.5 h staff meeting 07:00–07:30 (unpaid) = 7.5 h × R162,50 (R81,25 × 2) = R1218.75
...

Sheet Auditor Trail Linked
A1: Employee | B1: 1 Sat | D1: 2 Sun | F1: 3 Mon | H1: 4 Tue | J1: 5 Wed | L1: 6 Thu | N1: 7 Fri | P1: 6 MISSED SHIFTS | R1: Total Hours (Sat–Fri + Missed) | S1: Wages (linked) | T1: Fixed Deductions Due | U1: Fixed Deducted (edit) | V1: Fixed Outstanding After Payroll | W1: Additional Loan Due | X1: Additional Loan Deducted (edit) | Y1: Additional Loan Outstanding After Payroll | Z1: Total Deducted This Period | AA1: NET WAGE
B2: 2026-09-19 | D2: 2026-09-20 | F2: 2026-09-21 | H2: 2026-09-22 | J2: 2026-09-23 | L2: 2026-09-24 | N2: 2026-09-25 | P2: previous payroll, approved
B3: HR | C3: Amount | D3: HR | E3: Amount | F3: HR | G3: Amount | H3: HR | I3: Amount | J3: HR | K3: Amount | L3: HR | M3: Amount | N3: HR | O3: Amount | P3: HR | Q3: Amount
A4: Bhekizitha Maphosa | B4: =SUMIFS('Wage Detail Linked'!$O$5:$O$97,'Wage Detail Linked'!$B$5:$B$97,$A4,'Wage Detail Linked'!$C$5:$C$97,B$2,'Wage Detail Linked'!$E$5:$E$97,"") | C4: =IF(SUMIFS('Wage Detail Linked'!$O$5:$O$97,'Wage Detail Linked'!$B$5:$B$97,$A4,'Wage Detail Linked'!$C$5:$C$97,B$2,'Wage Detail Linked'!$E$5:$E$97,"")=0,IF(B4>0,ROUND(B4*90,2),0),ROUND(SUMIFS('Wage Detail Linked'!$R$5:$R$97,'Wage Detail Linked'!$B$5:$B$97,$A4,'Wage Detail Linked'!$C$5:$C$97,B$2,'Wage Detail Linked'!$E$5:$E$97,"")*B4/SUMIFS('Wage Detail Linked'!$O$5:$O$97,'Wage Detail Linked'!$B$5:$B$97,$A4,'Wage Detail Linked'!$C$5:$C$97,B$2,'Wage Detail Linked'!$E$5:$E$97,""),2)) | D4: =SUMIFS('Wage Detail Linked'!$O$5:$O$97,'Wage Detail Linked'!$B$5:$B$97,$A4,'Wage Detail Linked'!$C$5:$C$97,D$2,'Wage Detail Linked'!$E$5:$E$97,"") | E4: =IF(SUMIFS('Wage Detail Linked'!$O$5:$O$97,'Wage Detail Linked'!$B$5:$B$97,$A4,'Wage Detail Linked'!$C$5:$C$97,D$2,'Wage Detail Linked'!$E$5:$E$97,"")=0,IF(D4>0,ROUND(D4*90,2),0),ROUND(SUMIFS('Wage Detail Linked'!$R$5:$R$97,'Wage Detail Linked'!$B$5:$B$97,$A4,'Wage Detail Linked'!$C$5:$C$97,D$2,'Wage Detail Linked'!$E$5:$E$97,"")*D4/SUMIFS('Wage Detail Linked'!$O$5:$O$97,'Wage Detail Linked'!$B$5:$B$97,$A4,'Wage Detail Linked'!$C$5:$C$97,D$2,'Wage Detail Linked'!$E$5:$E$97,""),2)) | F4: =SUMIFS('Wage Detail Linked'!$O$5:$O$97,'Wage Detail Linked'!$B$5:$B$97,$A4,'Wage Detail Linked'!$C$5:$C$97,F$2,'Wage Detail Linked'!$E$5:$E$97,"") | G4: =IF(SUMIFS('Wage Detail Linked'!$O$5:$O$97,'Wage Detail Linked'!$B$5:$B$97,$A4,'Wage Detail Linked'!$C$5:$C$97,F$2,'Wage Detail Linked'!$E$5:$E$97,"")=0,IF(F4>0,ROUND(F4*90,2),0),ROUND(SUMIFS('Wage Detail Linked'!$R$5:$R$97,'Wage Detail Linked'!$B$5:$B$97,$A4,'Wage Detail Linked'!$C$5:$C$97,F$2,'Wage Detail Linked'!$E$5:$E$97,"")*F4/SUMIFS('Wage Detail Linked'!$O$5:$O$97,'Wage Detail Linked'!$B$5:$B$97,$A4,'Wage Detail Linked'!$C$5:$C$97,F$2,'Wage Detail Linked'!$E$5:$E$97,""),2)) | H4: =SUMIFS('Wage Detail Linked'!$O$5:$O$97,'Wage Detail Linked'!$B$5:$B$97,$A4,'Wage Detail Linked'!$C$5:$C$97,H$2,'Wage Detail Linked'!$E$5:$E$97,"") | I4: =IF(SUMIFS('Wage Detail Linked'!$O$5:$O$97,'Wage Detail Linked'!$B$5:$B$97,$A4,'Wage Detail Linked'!$C$5:$C$97,H$2,'Wage Detail Linked'!$E$5:$E$97,"")=0,IF(H4>0,ROUND(H4*90,2),0),ROUND(SUMIFS('Wage Detail Linked'!$R$5:$R$97,'Wage Detail Linked'!$B$5:$B$97,$A4,'Wage Detail Linked'!$C$5:$C$97,H$2,'Wage Detail Linked'!$E$5:$E$97,"")*H4/SUMIFS('Wage Detail Linked'!$O$5:$O$97,'Wage Detail Linked'!$B$5:$B$97,$A4,'Wage Detail Linked'!$C$5:$C$97,H$2,'Wage Detail Linked'!$E$5:$E$97,""),2)) | J4: =SUMIFS('Wage Detail Linked'!$O$5:$O$97,'Wage Detail Linked'!$B$5:$B$97,$A4,'Wage Detail Linked'!$C$5:$C$97,J$2,'Wage Detail Linked'!$E$5:$E$97,"") | K4: =IF(SUMIFS('Wage Detail Linked'!$O$5:$O$97,'Wage Detail Linked'!$B$5:$B$97,$A4,'Wage Detail Linked'!$C$5:$C$97,J$2,'Wage Detail Linked'!$E$5:$E$97,"")=0,IF(J4>0,ROUND(J4*90,2),0),ROUND(SUMIFS('Wage Detail Linked'!$R$5:$R$97,'Wage Detail Linked'!$B$5:$B$97,$A4,'Wage Detail Linked'!$C$5:$C$97,J$2,'Wage Detail Linked'!$E$5:$E$97,"")*J4/SUMIFS('Wage Detail Linked'!$O$5:$O$97,'Wage Detail Linked'!$B$5:$B$97,$A4,'Wage Detail Linked'!$C$5:$C$97,J$2,'Wage Detail Linked'!$E$5:$E$97,""),2)) | L4: =SUMIFS('Wage Detail Linked'!$O$5:$O$97,'Wage Detail Linked'!$B$5:$B$97,$A4,'Wage Detail Linked'!$C$5:$C$97,L$2,'Wage Detail Linked'!$E$5:$E$97,"") | M4: =IF(SUMIFS('Wage Detail Linked'!$O$5:$O$97,'Wage Detail Linked'!$B$5:$B$97,$A4,'Wage Detail Linked'!$C$5:$C$97,L$2,'Wage Detail Linked'!$E$5:$E$97,"")=0,IF(L4>0,ROUND(L4*90,2),0),ROUND(SUMIFS('Wage Detail Linked'!$R$5:$R$97,'Wage Detail Linked'!$B$5:$B$97,$A4,'Wage Detail Linked'!$C$5:$C$97,L$2,'Wage Detail Linked'!$E$5:$E$97,"")*L4/SUMIFS('Wage Detail Linked'!$O$5:$O$97,'Wage Detail Linked'!$B$5:$B$97,$A4,'Wage Detail Linked'!$C$5:$C$97,L$2,'Wage Detail Linked'!$E$5:$E$97,""),2)) | N4: =SUMIFS('Wage Detail Linked'!$O$5:$O$97,'Wage Detail Linked'!$B$5:$B$97,$A4,'Wage Detail Linked'!$C$5:$C$97,N$2,'Wage Detail Linked'!$E$5:$E$97,"") | O4: =IF(SUMIFS('Wage Detail Linked'!$O$5:$O$97,'Wage Detail Linked'!$B$5:$B$97,$A4,'Wage Detail Linked'!$C$5:$C$97,N$2,'Wage Detail Linked'!$E$5:$E$97,"")=0,IF(N4>0,ROUND(N4*90,2),0),ROUND(SUMIFS('Wage Detail Linked'!$R$5:$R$97,'Wage Detail Linked'!$B$5:$B$97,$A4,'Wage Detail Linked'!$C$5:$C$97,N$2,'Wage Detail Linked'!$E$5:$E$97,"")*N4/SUMIFS('Wage Detail Linked'!$O$5:$O$97,'Wage Detail Linked'!$B$5:$B$97,$A4,'Wage Detail Linked'!$C$5:$C$97,N$2,'Wage Detail Linked'!$E$5:$E$97,""),2)) | P4: ='Missed Shifts'!C7 | Q4: =IF('Missed Shifts'!C7=0,IF(P4>0,ROUND(P4*90,2),0),ROUND('Missed Shifts'!D7*P4/'Missed Shifts'!C7,2)) | R4: =SUM(B4,D4,F4,H4,J4,L4,N4,P4) | S4: =SUM(C4,E4,G4,I4,K4,M4,O4,Q4) | T4: 0 | U4: 0 | V4: =MAX(0,T4-U4) | W4: 0 | X4: 0 | Y4: =MAX(0,0-X4) | Z4: =U4+X4 | AA4: =MAX(0,S4-Z4)
A5: Daniel Motaung | B5: =SUMIFS('Wage Detail Linked'!$O$5:$O$97,'Wage Detail Linked'!$B$5:$B$97,$A5,'Wage Detail Linked'!$C$5:$C$97,B$2,'Wage Detail Linked'!$E$5:$E$97,"") | C5: =IF(SUMIFS('Wage Detail Linked'!$O$5:$O$97,'Wage Detail Linked'!$B$5:$B$97,$A5,'Wage Detail Linked'!$C$5:$C$97,B$2,'Wage Detail Linked'!$E$5:$E$97,"")=0,IF(B5>0,ROUND(B5*90,2),0),ROUND(SUMIFS('Wage Detail Linked'!$R$5:$R$97,'Wage Detail Linked'!$B$5:$B$97,$A5,'Wage Detail Linked'!$C$5:$C$97,B$2,'Wage Detail Linked'!$E$5:$E$97,"")*B5/SUMIFS('Wage Detail Linked'!$O$5:$O$97,'Wage Detail Linked'!$B$5:$B$97,$A5,'Wage Detail Linked'!$C$5:$C$97,B$2,'Wage Detail Linked'!$E$5:$E$97,""),2)) | D5: =SUMIFS('Wage Detail Linked'!$O$5:$O$97,'Wage Detail Linked'!$B$5:$B$97,$A5,'Wage Detail Linked'!$C$5:$C$97,D$2,'Wage Detail Linked'!$E$5:$E$97,"") | E5: =IF(SUMIFS('Wage Detail Linked'!$O$5:$O$97,'Wage Detail Linked'!$B$5:$B$97,$A5,'Wage Detail Linked'!$C$5:$C$97,D$2,'Wage Detail Linked'!$E$5:$E$97,"")=0,IF(D5>0,ROUND(D5*90,2),0),ROUND(SUMIFS('Wage Detail Linked'!$R$5:$R$97,'Wage Detail Linked'!$B$5:$B$97,$A5,'Wage Detail Linked'!$C$5:$C$97,D$2,'Wage Detail Linked'!$E$5:$E$97,"")*D5/SUMIFS('Wage Detail Linked'!$O$5:$O$97,'Wage Detail Linked'!$B$5:$B$97,$A5,'Wage Detail Linked'!$C$5:$C$97,D$2,'Wage Detail Linked'!$E$5:$E$97,""),2)) | F5: =SUMIFS('Wage Detail Linked'!$O$5:$O$97,'Wage Detail Linked'!$B$5:$B$97,$A5,'Wage Detail Linked'!$C$5:$C$97,F$2,'Wage Detail Linked'!$E$5:$E$97,"") | G5: =IF(SUMIFS('Wage Detail Linked'!$O$5:$O$97,'Wage Detail Linked'!$B$5:$B$97,$A5,'Wage Detail Linked'!$C$5:$C$97,F$2,'Wage Detail Linked'!$E$5:$E$97,"")=0,IF(F5>0,ROUND(F5*90,2),0),ROUND(SUMIFS('Wage Detail Linked'!$R$5:$R$97,'Wage Detail Linked'!$B$5:$B$97,$A5,'Wage Detail Linked'!$C$5:$C$97,F$2,'Wage Detail Linked'!$E$5:$E$97,"")*F5/SUMIFS('Wage Detail Linked'!$O$5:$O$97,'Wage Detail Linked'!$B$5:$B$97,$A5,'Wage Detail Linked'!$C$5:$C$97,F$2,'Wage Detail Linked'!$E$5:$E$97,""),2)) | H5: =SUMIFS('Wage Detail Linked'!$O$5:$O$97,'Wage Detail Linked'!$B$5:$B$97,$A5,'Wage Detail Linked'!$C$5:$C$97,H$2,'Wage Detail Linked'!$E$5:$E$97,"") | I5: =IF(SUMIFS('Wage Detail Linked'!$O$5:$O$97,'Wage Detail Linked'!$B$5:$B$97,$A5,'Wage Detail Linked'!$C$5:$C$97,H$2,'Wage Detail Linked'!$E$5:$E$97,"")=0,IF(H5>0,ROUND(H5*90,2),0),ROUND(SUMIFS('Wage Detail Linked'!$R$5:$R$97,'Wage Detail Linked'!$B$5:$B$97,$A5,'Wage Detail Linked'!$C$5:$C$97,H$2,'Wage Detail Linked'!$E$5:$E$97,"")*H5/SUMIFS('Wage Detail Linked'!$O$5:$O$97,'Wage Detail Linked'!$B$5:$B$97,$A5,'Wage Detail Linked'!$C$5:$C$97,H$2,'Wage Detail Linked'!$E$5:$E$97,""),2)) | J5: =SUMIFS('Wage Detail Linked'!$O$5:$O$97,'Wage Detail Linked'!$B$5:$B$97,$A5,'Wage Detail Linked'!$C$5:$C$97,J$2,'Wage Detail Linked'!$E$5:$E$97,"") | K5: =IF(SUMIFS('Wage Detail Linked'!$O$5:$O$97,'Wage Detail Linked'!$B$5:$B$97,$A5,'Wage Detail Linked'!$C$5:$C$97,J$2,'Wage Detail Linked'!$E$5:$E$97,"")=0,IF(J5>0,ROUND(J5*90,2),0),ROUND(SUMIFS('Wage Detail Linked'!$R$5:$R$97,'Wage Detail Linked'!$B$5:$B$97,$A5,'Wage Detail Linked'!$C$5:$C$97,J$2,'Wage Detail Linked'!$E$5:$E$97,"")*J5/SUMIFS('Wage Detail Linked'!$O$5:$O$97,'Wage Detail Linked'!$B$5:$B$97,$A5,'Wage Detail Linked'!$C$5:$C$97,J$2,'Wage Detail Linked'!$E$5:$E$97,""),2)) | L5: =SUMIFS('Wage Detail Linked'!$O$5:$O$97,'Wage Detail Linked'!$B$5:$B$97,$A5,'Wage Detail Linked'!$C$5:$C$97,L$2,'Wage Detail Linked'!$E$5:$E$97,"") | M5: =IF(SUMIFS('Wage Detail Linked'!$O$5:$O$97,'Wage Detail Linked'!$B$5:$B$97,$A5,'Wage Detail Linked'!$C$5:$C$97,L$2,'Wage Detail Linked'!$E$5:$E$97,"")=0,IF(L5>0,ROUND(L5*90,2),0),ROUND(SUMIFS('Wage Detail Linked'!$R$5:$R$97,'Wage Detail Linked'!$B$5:$B$97,$A5,'Wage Detail Linked'!$C$5:$C$97,L$2,'Wage Detail Linked'!$E$5:$E$97,"")*L5/SUMIFS('Wage Detail Linked'!$O$5:$O$97,'Wage Detail Linked'!$B$5:$B$97,$A5,'Wage Detail Linked'!$C$5:$C$97,L$2,'Wage Detail Linked'!$E$5:$E$97,""),2)) | N5: =SUMIFS('Wage Detail Linked'!$O$5:$O$97,'Wage Detail Linked'!$B$5:$B$97,$A5,'Wage Detail Linked'!$C$5:$C$97,N$2,'Wage Detail Linked'!$E$5:$E$97,"") | O5: =IF(SUMIFS('Wage Detail Linked'!$O$5:$O$97,'Wage Detail Linked'!$B$5:$B$97,$A5,'Wage Detail Linked'!$C$5:$C$97,N$2,'Wage Detail Linked'!$E$5:$E$97,"")=0,IF(N5>0,ROUND(N5*90,2),0),ROUND(SUMIFS('Wage Detail Linked'!$R$5:$R$97,'Wage Detail Linked'!$B$5:$B$97,$A5,'Wage Detail Linked'!$C$5:$C$97,N$2,'Wage Detail Linked'!$E$5:$E$97,"")*N5/SUMIFS('Wage Detail Linked'!$O$5:$O$97,'Wage Detail Linked'!$B$5:$B$97,$A5,'Wage Detail Linked'!$C$5:$C$97,N$2,'Wage Detail Linked'!$E$5:$E$97,""),2)) | P5: =0 | Q5: =IF(P5>0,ROUND(P5*90,2),0) | R5: =SUM(B5,D5,F5,H5,J5,L5,N5,P5) | S5: =SUM(C5,E5,G5,I5,K5,M5,O5,Q5) | T5: 0 | U5: 0 | V5: =MAX(0,T5-U5) | W5: 0 | X5: 0 | Y5: =MAX(0,0-X5) | Z5: =U5+X5 | AA5: =MAX(0,S5-Z5)
A6: Erence Mngomezulu | B6: =SUMIFS('Wage Detail Linked'!$O$5:$O$97,'Wage Detail Linked'!$B$5:$B$97,$A6,'Wage Detail Linked'!$C$5:$C$97,B$2,'Wage Detail Linked'!$E$5:$E$97,"") | C6: =IF(SUMIFS('Wage Detail Linked'!$O$5:$O$97,'Wage Detail Linked'!$B$5:$B$97,$A6,'Wage Detail Linked'!$C$5:$C$97,B$2,'Wage Detail Linked'!$E$5:$E$97,"")=0,IF(B6>0,ROUND(B6*90,2),0),ROUND(SUMIFS('Wage Detail Linked'!$R$5:$R$97,'Wage Detail Linked'!$B$5:$B$97,$A6,'Wage Detail Linked'!$C$5:$C$97,B$2,'Wage Detail Linked'!$E$5:$E$97,"")*B6/SUMIFS('Wage Detail Linked'!$O$5:$O$97,'Wage Detail Linked'!$B$5:$B$97,$A6,'Wage Detail Linked'!$C$5:$C$97,B$2,'Wage Detail Linked'!$E$5:$E$97,""),2)) | D6: =SUMIFS('Wage Detail Linked'!$O$5:$O$97,'Wage Detail Linked'!$B$5:$B$97,$A6,'Wage Detail Linked'!$C$5:$C$97,D$2,'Wage Detail Linked'!$E$5:$E$97,"") | E6: =IF(SUMIFS('Wage Detail Linked'!$O$5:$O$97,'Wage Detail Linked'!$B$5:$B$97,$A6,'Wage Detail Linked'!$C$5:$C$97,D$2,'Wage Detail Linked'!$E$5:$E$97,"")=0,IF(D6>0,ROUND(D6*90,2),0),ROUND(SUMIFS('Wage Detail Linked'!$R$5:$R$97,'Wage Detail Linked'!$B$5:$B$97,$A6,'Wage Detail Linked'!$C$5:$C$97,D$2,'Wage Detail Linked'!$E$5:$E$97,"")*D6/SUMIFS('Wage Detail Linked'!$O$5:$O$97,'Wage Detail Linked'!$B$5:$B$97,$A6,'Wage Detail Linked'!$C$5:$C$97,D$2,'Wage Detail Linked'!$E$5:$E$97,""),2)) | F6: =SUMIFS('Wage Detail Linked'!$O$5:$O$97,'Wage Detail Linked'!$B$5:$B$97,$A6,'Wage Detail Linked'!$C$5:$C$97,F$2,'Wage Detail Linked'!$E$5:$E$97,"") | G6: =IF(SUMIFS('Wage Detail Linked'!$O$5:$O$97,'Wage Detail Linked'!$B$5:$B$97,$A6,'Wage Detail Linked'!$C$5:$C$97,F$2,'Wage Detail Linked'!$E$5:$E$97,"")=0,IF(F6>0,ROUND(F6*90,2),0),ROUND(SUMIFS('Wage Detail Linked'!$R$5:$R$97,'Wage Detail Linked'!$B$5:$B$97,$A6,'Wage Detail Linked'!$C$5:$C$97,F$2,'Wage Detail Linked'!$E$5:$E$97,"")*F6/SUMIFS('Wage Detail Linked'!$O$5:$O$97,'Wage Detail Linked'!$B$5:$B$97,$A6,'Wage Detail Linked'!$C$5:$C$97,F$2,'Wage Detail Linked'!$E$5:$E$97,""),2)) | H6: =SUMIFS('Wage Detail Linked'!$O$5:$O$97,'Wage Detail Linked'!$B$5:$B$97,$A6,'Wage Detail Linked'!$C$5:$C$97,H$2,'Wage Detail Linked'!$E$5:$E$97,"") | I6: =IF(SUMIFS('Wage Detail Linked'!$O$5:$O$97,'Wage Detail Linked'!$B$5:$B$97,$A6,'Wage Detail Linked'!$C$5:$C$97,H$2,'Wage Detail Linked'!$E$5:$E$97,"")=0,IF(H6>0,ROUND(H6*90,2),0),ROUND(SUMIFS('Wage Detail Linked'!$R$5:$R$97,'Wage Detail Linked'!$B$5:$B$97,$A6,'Wage Detail Linked'!$C$5:$C$97,H$2,'Wage Detail Linked'!$E$5:$E$97,"")*H6/SUMIFS('Wage Detail Linked'!$O$5:$O$97,'Wage Detail Linked'!$B$5:$B$97,$A6,'Wage Detail Linked'!$C$5:$C$97,H$2,'Wage Detail Linked'!$E$5:$E$97,""),2)) | J6: =SUMIFS('Wage Detail Linked'!$O$5:$O$97,'Wage Detail Linked'!$B$5:$B$97,$A6,'Wage Detail Linked'!$C$5:$C$97,J$2,'Wage Detail Linked'!$E$5:$E$97,"") | K6: =IF(SUMIFS('Wage Detail Linked'!$O$5:$O$97,'Wage Detail Linked'!$B$5:$B$97,$A6,'Wage Detail Linked'!$C$5:$C$97,J$2,'Wage Detail Linked'!$E$5:$E$97,"")=0,IF(J6>0,ROUND(J6*90,2),0),ROUND(SUMIFS('Wage Detail Linked'!$R$5:$R$97,'Wage Detail Linked'!$B$5:$B$97,$A6,'Wage Detail Linked'!$C$5:$C$97,J$2,'Wage Detail Linked'!$E$5:$E$97,"")*J6/SUMIFS('Wage Detail Linked'!$O$5:$O$97,'Wage Detail Linked'!$B$5:$B$97,$A6,'Wage Detail Linked'!$C$5:$C$97,J$2,'Wage Detail Linked'!$E$5:$E$97,""),2)) | L6: =SUMIFS('Wage Detail Linked'!$O$5:$O$97,'Wage Detail Linked'!$B$5:$B$97,$A6,'Wage Detail Linked'!$C$5:$C$97,L$2,'Wage Detail Linked'!$E$5:$E$97,"") | M6: =IF(SUMIFS('Wage Detail Linked'!$O$5:$O$97,'Wage Detail Linked'!$B$5:$B$97,$A6,'Wage Detail Linked'!$C$5:$C$97,L$2,'Wage Detail Linked'!$E$5:$E$97,"")=0,IF(L6>0,ROUND(L6*90,2),0),ROUND(SUMIFS('Wage Detail Linked'!$R$5:$R$97,'Wage Detail Linked'!$B$5:$B$97,$A6,'Wage Detail Linked'!$C$5:$C$97,L$2,'Wage Detail Linked'!$E$5:$E$97,"")*L6/SUMIFS('Wage Detail Linked'!$O$5:$O$97,'Wage Detail Linked'!$B$5:$B$97,$A6,'Wage Detail Linked'!$C$5:$C$97,L$2,'Wage Detail Linked'!$E$5:$E$97,""),2)) | N6: =SUMIFS('Wage Detail Linked'!$O$5:$O$97,'Wage Detail Linked'!$B$5:$B$97,$A6,'Wage Detail Linked'!$C$5:$C$97,N$2,'Wage Detail Linked'!$E$5:$E$97,"") | O6: =IF(SUMIFS('Wage Detail Linked'!$O$5:$O$97,'Wage Detail Linked'!$B$5:$B$97,$A6,'Wage Detail Linked'!$C$5:$C$97,N$2,'Wage Detail Linked'!$E$5:$E$97,"")=0,IF(N6>0,ROUND(N6*90,2),0),ROUND(SUMIFS('Wage Detail Linked'!$R$5:$R$97,'Wage Detail Linked'!$B$5:$B$97,$A6,'Wage Detail Linked'!$C$5:$C$97,N$2,'Wage Detail Linked'!$E$5:$E$97,"")*N6/SUMIFS('Wage Detail Linked'!$O$5:$O$97,'Wage Detail Linked'!$B$5:$B$97,$A6,'Wage Detail Linked'!$C$5:$C$97,N$2,'Wage Detail Linked'!$E$5:$E$97,""),2)) | P6: ='Missed Shifts'!C12 | Q6: =IF('Missed Shifts'!C12=0,IF(P6>0,ROUND(P6*90,2),0),ROUND('Missed Shifts'!D12*P6/'Missed Shifts'!C12,2)) | R6: =SUM(B6,D6,F6,H6,J6,L6,N6,P6) | S6: =SUM(C6,E6,G6,I6,K6,M6,O6,Q6) | T6: 0 | U6: 0 | V6: =MAX(0,T6-U6) | W6: 0 | X6: 0 | Y6: =MAX(0,0-X6) | Z6: =U6+X6 | AA6: =MAX(0,S6-Z6)
A7: Erick Mpho Molefe | B7: =SUMIFS('Wage Detail Linked'!$O$5:$O$97,'Wage Detail Linked'!$B$5:$B$97,$A7,'Wage Detail Linked'!$C$5:$C$97,B$2,'Wage Detail Linked'!$E$5:$E$97,"") | C7: =IF(SUMIFS('Wage Detail Linked'!$O$5:$O$97,'Wage Detail Linked'!$B$5:$B$97,$A7,'Wage Detail Linked'!$C$5:$C$97,B$2,'Wage Detail Linked'!$E$5:$E$97,"")=0,IF(B7>0,ROUND(B7*90,2),0),ROUND(SUMIFS('Wage Detail Linked'!$R$5:$R$97,'Wage Detail Linked'!$B$5:$B$97,$A7,'Wage Detail Linked'!$C$5:$C$97,B$2,'Wage Detail Linked'!$E$5:$E$97,"")*B7/SUMIFS('Wage Detail Linked'!$O$5:$O$97,'Wage Detail Linked'!$B$5:$B$97,$A7,'Wage Detail Linked'!$C$5:$C$97,B$2,'Wage Detail Linked'!$E$5:$E$97,""),2)) | D7: =SUMIFS('Wage Detail Linked'!$O$5:$O$97,'Wage Detail Linked'!$B$5:$B$97,$A7,'Wage Detail Linked'!$C$5:$C$97,D$2,'Wage Detail Linked'!$E$5:$E$97,"") | E7: =IF(SUMIFS('Wage Detail Linked'!$O$5:$O$97,'Wage Detail Linked'!$B$5:$B$97,$A7,'Wage Detail Linked'!$C$5:$C$97,D$2,'Wage Detail Linked'!$E$5:$E$97,"")=0,IF(D7>0,ROUND(D7*90,2),0),ROUND(SUMIFS('Wage Detail Linked'!$R$5:$R$97,'Wage Detail Linked'!$B$5:$B$97,$A7,'Wage Detail Linked'!$C$5:$C$97,D$2,'Wage Detail Linked'!$E$5:$E$97,"")*D7/SUMIFS('Wage Detail Linked'!$O$5:$O$97,'Wage Detail Linked'!$B$5:$B$97,$A7,'Wage Detail Linked'!$C$5:$C$97,D$2,'Wage Detail Linked'!$E$5:$E$97,""),2)) | F7: =SUMIFS('Wage Detail Linked'!$O$5:$O$97,'Wage Detail Linked'!$B$5:$B$97,$A7,'Wage Detail Linked'!$C$5:$C$97,F$2,'Wage Detail Linked'!$E$5:$E$97,"") | G7: =IF(SUMIFS('Wage Detail Linked'!$O$5:$O$97,'Wage Detail Linked'!$B$5:$B$97,$A7,'Wage Detail Linked'!$C$5:$C$97,F$2,'Wage Detail Linked'!$E$5:$E$97,"")=0,IF(F7>0,ROUND(F7*90,2),0),ROUND(SUMIFS('Wage Detail Linked'!$R$5:$R$97,'Wage Detail Linked'!$B$5:$B$97,$A7,'Wage Detail Linked'!$C$5:$C$97,F$2,'Wage Detail Linked'!$E$5:$E$97,"")*F7/SUMIFS('Wage Detail Linked'!$O$5:$O$97,'Wage Detail Linked'!$B$5:$B$97,$A7,'Wage Detail Linked'!$C$5:$C$97,F$2,'Wage Detail Linked'!$E$5:$E$97,""),2)) | H7: =SUMIFS('Wage Detail Linked'!$O$5:$O$97,'Wage Detail Linked'!$B$5:$B$97,$A7,'Wage Detail Linked'!$C$5:$C$97,H$2,'Wage Detail Linked'!$E$5:$E$97,"") | I7: =IF(SUMIFS('Wage Detail Linked'!$O$5:$O$97,'Wage Detail Linked'!$B$5:$B$97,$A7,'Wage Detail Linked'!$C$5:$C$97,H$2,'Wage Detail Linked'!$E$5:$E$97,"")=0,IF(H7>0,ROUND(H7*90,2),0),ROUND(SUMIFS('Wage Detail Linked'!$R$5:$R$97,'Wage Detail Linked'!$B$5:$B$97,$A7,'Wage Detail Linked'!$C$5:$C$97,H$2,'Wage Detail Linked'!$E$5:$E$97,"")*H7/SUMIFS('Wage Detail Linked'!$O$5:$O$97,'Wage Detail Linked'!$B$5:$B$97,$A7,'Wage Detail Linked'!$C$5:$C$97,H$2,'Wage Detail Linked'!$E$5:$E$97,""),2)) | J7: =SUMIFS('Wage Detail Linked'!$O$5:$O$97,'Wage Detail Linked'!$B$5:$B$97,$A7,'Wage Detail Linked'!$C$5:$C$97,J$2,'Wage Detail Linked'!$E$5:$E$97,"") | K7: =IF(SUMIFS('Wage Detail Linked'!$O$5:$O$97,'Wage Detail Linked'!$B$5:$B$97,$A7,'Wage Detail Linked'!$C$5:$C$97,J$2,'Wage Detail Linked'!$E$5:$E$97,"")=0,IF(J7>0,ROUND(J7*90,2),0),ROUND(SUMIFS('Wage Detail Linked'!$R$5:$R$97,'Wage Detail Linked'!$B$5:$B$97,$A7,'Wage Detail Linked'!$C$5:$C$97,J$2,'Wage Detail Linked'!$E$5:$E$97,"")*J7/SUMIFS('Wage Detail Linked'!$O$5:$O$97,'Wage Detail Linked'!$B$5:$B$97,$A7,'Wage Detail Linked'!$C$5:$C$97,J$2,'Wage Detail Linked'!$E$5:$E$97,""),2)) | L7: =SUMIFS('Wage Detail Linked'!$O$5:$O$97,'Wage Detail Linked'!$B$5:$B$97,$A7,'Wage Detail Linked'!$C$5:$C$97,L$2,'Wage Detail Linked'!$E$5:$E$97,"") | M7: =IF(SUMIFS('Wage Detail Linked'!$O$5:$O$97,'Wage Detail Linked'!$B$5:$B$97,$A7,'Wage Detail Linked'!$C$5:$C$97,L$2,'Wage Detail Linked'!$E$5:$E$97,"")=0,IF(L7>0,ROUND(L7*90,2),0),ROUND(SUMIFS('Wage Detail Linked'!$R$5:$R$97,'Wage Detail Linked'!$B$5:$B$97,$A7,'Wage Detail Linked'!$C$5:$C$97,L$2,'Wage Detail Linked'!$E$5:$E$97,"")*L7/SUMIFS('Wage Detail Linked'!$O$5:$O$97,'Wage Detail Linked'!$B$5:$B$97,$A7,'Wage Detail Linked'!$C$5:$C$97,L$2,'Wage Detail Linked'!$E$5:$E$97,""),2)) | N7: =SUMIFS('Wage Detail Linked'!$O$5:$O$97,'Wage Detail Linked'!$B$5:$B$97,$A7,'Wage Detail Linked'!$C$5:$C$97,N$2,'Wage Detail Linked'!$E$5:$E$97,"") | O7: =IF(SUMIFS('Wage Detail Linked'!$O$5:$O$97,'Wage Detail Linked'!$B$5:$B$97,$A7,'Wage Detail Linked'!$C$5:$C$97,N$2,'Wage Detail Linked'!$E$5:$E$97,"")=0,IF(N7>0,ROUND(N7*90,2),0),ROUND(SUMIFS('Wage Detail Linked'!$R$5:$R$97,'Wage Detail Linked'!$B$5:$B$97,$A7,'Wage Detail Linked'!$C$5:$C$97,N$2,'Wage Detail Linked'!$E$5:$E$97,"")*N7/SUMIFS('Wage Detail Linked'!$O$5:$O$97,'Wage Detail Linked'!$B$5:$B$97,$A7,'Wage Detail Linked'!$C$5:$C$97,N$2,'Wage Detail Linked'!$E$5:$E$97,""),2)) | P7: ='Missed Shifts'!C15 | Q7: =IF('Missed Shifts'!C15=0,IF(P7>0,ROUND(P7*90,2),0),ROUND('Missed Shifts'!D15*P7/'Missed Shifts'!C15,2)) | R7: =SUM(B7,D7,F7,H7,J7,L7,N7,P7) | S7: =SUM(C7,E7,G7,I7,K7,M7,O7,Q7) | T7: 1000 | U7: 1000 | V7: =MAX(0,T7-U7) | W7: 500 | X7: 500 | Y7: =MAX(0,1000-X7) | Z7: =U7+X7 | AA7: =MAX(0,S7-Z7)
A8: Givemore Chifetete Kuziwa | B8: =SUMIFS('Wage Detail Linked'!$O$5:$O$97,'Wage Detail Linked'!$B$5:$B$97,$A8,'Wage Detail Linked'!$C$5:$C$97,B$2,'Wage Detail Linked'!$E$5:$E$97,"") | C8: =IF(SUMIFS('Wage Detail Linked'!$O$5:$O$97,'Wage Detail Linked'!$B$5:$B$97,$A8,'Wage Detail Linked'!$C$5:$C$97,B$2,'Wage Detail Linked'!$E$5:$E$97,"")=0,IF(B8>0,ROUND(B8*90,2),0),ROUND(SUMIFS('Wage Detail Linked'!$R$5:$R$97,'Wage Detail Linked'!$B$5:$B$97,$A8,'Wage Detail Linked'!$C$5:$C$97,B$2,'Wage Detail Linked'!$E$5:$E$97,"")*B8/SUMIFS('Wage Detail Linked'!$O$5:$O$97,'Wage Detail Linked'!$B$5:$B$97,$A8,'Wage Detail Linked'!$C$5:$C$97,B$2,'Wage Detail Linked'!$E$5:$E$97,""),2)) | D8: =SUMIFS('Wage Detail Linked'!$O$5:$O$97,'Wage Detail Linked'!$B$5:$B$97,$A8,'Wage Detail Linked'!$C$5:$C$97,D$2,'Wage Detail Linked'!$E$5:$E$97,"") | E8: =IF(SUMIFS('Wage Detail Linked'!$O$5:$O$97,'Wage Detail Linked'!$B$5:$B$97,$A8,'Wage Detail Linked'!$C$5:$C$97,D$2,'Wage Detail Linked'!$E$5:$E$97,"")=0,IF(D8>0,ROUND(D8*90,2),0),ROUND(SUMIFS('Wage Detail Linked'!$R$5:$R$97,'Wage Detail Linked'!$B$5:$B$97,$A8,'Wage Detail Linked'!$C$5:$C$97,D$2,'Wage Detail Linked'!$E$5:$E$97,"")*D8/SUMIFS('Wage Detail Linked'!$O$5:$O$97,'Wage Detail Linked'!$B$5:$B$97,$A8,'Wage Detail Linked'!$C$5:$C$97,D$2,'Wage Detail Linked'!$E$5:$E$97,""),2)) | F8: =SUMIFS('Wage Detail Linked'!$O$5:$O$97,'Wage Detail Linked'!$B$5:$B$97,$A8,'Wage Detail Linked'!$C$5:$C$97,F$2,'Wage Detail Linked'!$E$5:$E$97,"") | G8: =IF(SUMIFS('Wage Detail Linked'!$O$5:$O$97,'Wage Detail Linked'!$B$5:$B$97,$A8,'Wage Detail Linked'!$C$5:$C$97,F$2,'Wage Detail Linked'!$E$5:$E$97,"")=0,IF(F8>0,ROUND(F8*90,2),0),ROUND(SUMIFS('Wage Detail Linked'!$R$5:$R$97,'Wage Detail Linked'!$B$5:$B$97,$A8,'Wage Detail Linked'!$C$5:$C$97,F$2,'Wage Detail Linked'!$E$5:$E$97,"")*F8/SUMIFS('Wage Detail Linked'!$O$5:$O$97,'Wage Detail Linked'!$B$5:$B$97,$A8,'Wage Detail Linked'!$C$5:$C$97,F$2,'Wage Detail Linked'!$E$5:$E$97,""),2)) | H8: =SUMIFS('Wage Detail Linked'!$O$5:$O$97,'Wage Detail Linked'!$B$5:$B$97,$A8,'Wage Detail Linked'!$C$5:$C$97,H$2,'Wage Detail Linked'!$E$5:$E$97,"") | I8: =IF(SUMIFS('Wage Detail Linked'!$O$5:$O$97,'Wage Detail Linked'!$B$5:$B$97,$A8,'Wage Detail Linked'!$C$5:$C$97,H$2,'Wage Detail Linked'!$E$5:$E$97,"")=0,IF(H8>0,ROUND(H8*90,2),0),ROUND(SUMIFS('Wage Detail Linked'!$R$5:$R$97,'Wage Detail Linked'!$B$5:$B$97,$A8,'Wage Detail Linked'!$C$5:$C$97,H$2,'Wage Detail Linked'!$E$5:$E$97,"")*H8/SUMIFS('Wage Detail Linked'!$O$5:$O$97,'Wage Detail Linked'!$B$5:$B$97,$A8,'Wage Detail Linked'!$C$5:$C$97,H$2,'Wage Detail Linked'!$E$5:$E$97,""),2)) | J8: =SUMIFS('Wage Detail Linked'!$O$5:$O$97,'Wage Detail Linked'!$B$5:$B$97,$A8,'Wage Detail Linked'!$C$5:$C$97,J$2,'Wage Detail Linked'!$E$5:$E$97,"") | K8: =IF(SUMIFS('Wage Detail Linked'!$O$5:$O$97,'Wage Detail Linked'!$B$5:$B$97,$A8,'Wage Detail Linked'!$C$5:$C$97,J$2,'Wage Detail Linked'!$E$5:$E$97,"")=0,IF(J8>0,ROUND(J8*90,2),0),ROUND(SUMIFS('Wage Detail Linked'!$R$5:$R$97,'Wage Detail Linked'!$B$5:$B$97,$A8,'Wage Detail Linked'!$C$5:$C$97,J$2,'Wage Detail Linked'!$E$5:$E$97,"")*J8/SUMIFS('Wage Detail Linked'!$O$5:$O$97,'Wage Detail Linked'!$B$5:$B$97,$A8,'Wage Detail Linked'!$C$5:$C$97,J$2,'Wage Detail Linked'!$E$5:$E$97,""),2)) | L8: =SUMIFS('Wage Detail Linked'!$O$5:$O$97,'Wage Detail Linked'!$B$5:$B$97,$A8,'Wage Detail Linked'!$C$5:$C$97,L$2,'Wage Detail Linked'!$E$5:$E$97,"") | M8: =IF(SUMIFS('Wage Detail Linked'!$O$5:$O$97,'Wage Detail Linked'!$B$5:$B$97,$A8,'Wage Detail Linked'!$C$5:$C$97,L$2,'Wage Detail Linked'!$E$5:$E$97,"")=0,IF(L8>0,ROUND(L8*90,2),0),ROUND(SUMIFS('Wage Detail Linked'!$R$5:$R$97,'Wage Detail Linked'!$B$5:$B$97,$A8,'Wage Detail Linked'!$C$5:$C$97,L$2,'Wage Detail Linked'!$E$5:$E$97,"")*L8/SUMIFS('Wage Detail Linked'!$O$5:$O$97,'Wage Detail Linked'!$B$5:$B$97,$A8,'Wage Detail Linked'!$C$5:$C$97,L$2,'Wage Detail Linked'!$E$5:$E$97,""),2)) | N8: =SUMIFS('Wage Detail Linked'!$O$5:$O$97,'Wage Detail Linked'!$B$5:$B$97,$A8,'Wage Detail Linked'!$C$5:$C$97,N$2,'Wage Detail Linked'!$E$5:$E$97,"") | O8: =IF(SUMIFS('Wage Detail Linked'!$O$5:$O$97,'Wage Detail Linked'!$B$5:$B$97,$A8,'Wage Detail Linked'!$C$5:$C$97,N$2,'Wage Detail Linked'!$E$5:$E$97,"")=0,IF(N8>0,ROUND(N8*90,2),0),ROUND(SUMIFS('Wage Detail Linked'!$R$5:$R$97,'Wage Detail Linked'!$B$5:$B$97,$A8,'Wage Detail Linked'!$C$5:$C$97,N$2,'Wage Detail Linked'!$E$5:$E$97,"")*N8/SUMIFS('Wage Detail Linked'!$O$5:$O$97,'Wage Detail Linked'!$B$5:$B$97,$A8,'Wage Detail Linked'!$C$5:$C$97,N$2,'Wage Detail Linked'!$E$5:$E$97,""),2)) | P8: ='Missed Shifts'!C18 | Q8: =IF('Missed Shifts'!C18=0,IF(P8>0,ROUND(P8*90,2),0),ROUND('Missed Shifts'!D18*P8/'Missed Shifts'!C18,2)) | R8: =SUM(B8,D8,F8,H8,J8,L8,N8,P8) | S8: =SUM(C8,E8,G8,I8,K8,M8,O8,Q8) | T8: 0 | U8: 0 | V8: =MAX(0,T8-U8) | W8: 0 | X8: 0 | Y8: =MAX(0,0-X8) | Z8: =U8+X8 | AA8: =MAX(0,S8-Z8)
A9: Isaac Mbele | B9: =SUMIFS('Wage Detail Linked'!$O$5:$O$97,'Wage Detail Linked'!$B$5:$B$97,$A9,'Wage Detail Linked'!$C$5:$C$97,B$2,'Wage Detail Linked'!$E$5:$E$97,"") | C9: =IF(SUMIFS('Wage Detail Linked'!$O$5:$O$97,'Wage Detail Linked'!$B$5:$B$97,$A9,'Wage Detail Linked'!$C$5:$C$97,B$2,'Wage Detail Linked'!$E$5:$E$97,"")=0,IF(B9>0,ROUND(B9*90,2),0),ROUND(SUMIFS('Wage Detail Linked'!$R$5:$R$97,'Wage Detail Linked'!$B$5:$B$97,$A9,'Wage Detail Linked'!$C$5:$C$97,B$2,'Wage Detail Linked'!$E$5:$E$97,"")*B9/SUMIFS('Wage Detail Linked'!$O$5:$O$97,'Wage Detail Linked'!$B$5:$B$97,$A9,'Wage Detail Linked'!$C$5:$C$97,B$2,'Wage Detail Linked'!$E$5:$E$97,""),2)) | D9: =SUMIFS('Wage Detail Linked'!$O$5:$O$97,'Wage Detail Linked'!$B$5:$B$97,$A9,'Wage Detail Linked'!$C$5:$C$97,D$2,'Wage Detail Linked'!$E$5:$E$97,"") | E9: =IF(SUMIFS('Wage Detail Linked'!$O$5:$O$97,'Wage Detail Linked'!$B$5:$B$97,$A9,'Wage Detail Linked'!$C$5:$C$97,D$2,'Wage Detail Linked'!$E$5:$E$97,"")=0,IF(D9>0,ROUND(D9*90,2),0),ROUND(SUMIFS('Wage Detail Linked'!$R$5:$R$97,'Wage Detail Linked'!$B$5:$B$97,$A9,'Wage Detail Linked'!$C$5:$C$97,D$2,'Wage Detail Linked'!$E$5:$E$97,"")*D9/SUMIFS('Wage Detail Linked'!$O$5:$O$97,'Wage Detail Linked'!$B$5:$B$97,$A9,'Wage Detail Linked'!$C$5:$C$97,D$2,'Wage Detail Linked'!$E$5:$E$97,""),2)) | F9: =SUMIFS('Wage Detail Linked'!$O$5:$O$97,'Wage Detail Linked'!$B$5:$B$97,$A9,'Wage Detail Linked'!$C$5:$C$97,F$2,'Wage Detail Linked'!$E$5:$E$97,"") | G9: =IF(SUMIFS('Wage Detail Linked'!$O$5:$O$97,'Wage Detail Linked'!$B$5:$B$97,$A9,'Wage Detail Linked'!$C$5:$C$97,F$2,'Wage Detail Linked'!$E$5:$E$97,"")=0,IF(F9>0,ROUND(F9*90,2),0),ROUND(SUMIFS('Wage Detail Linked'!$R$5:$R$97,'Wage Detail Linked'!$B$5:$B$97,$A9,'Wage Detail Linked'!$C$5:$C$97,F$2,'Wage Detail Linked'!$E$5:$E$97,"")*F9/SUMIFS('Wage Detail Linked'!$O$5:$O$97,'Wage Detail Linked'!$B$5:$B$97,$A9,'Wage Detail Linked'!$C$5:$C$97,F$2,'Wage Detail Linked'!$E$5:$E$97,""),2)) | H9: =SUMIFS('Wage Detail Linked'!$O$5:$O$97,'Wage Detail Linked'!$B$5:$B$97,$A9,'Wage Detail Linked'!$C$5:$C$97,H$2,'Wage Detail Linked'!$E$5:$E$97,"") | I9: =IF(SUMIFS('Wage Detail Linked'!$O$5:$O$97,'Wage Detail Linked'!$B$5:$B$97,$A9,'Wage Detail Linked'!$C$5:$C$97,H$2,'Wage Detail Linked'!$E$5:$E$97,"")=0,IF(H9>0,ROUND(H9*90,2),0),ROUND(SUMIFS('Wage Detail Linked'!$R$5:$R$97,'Wage Detail Linked'!$B$5:$B$97,$A9,'Wage Detail Linked'!$C$5:$C$97,H$2,'Wage Detail Linked'!$E$5:$E$97,"")*H9/SUMIFS('Wage Detail Linked'!$O$5:$O$97,'Wage Detail Linked'!$B$5:$B$97,$A9,'Wage Detail Linked'!$C$5:$C$97,H$2,'Wage Detail Linked'!$E$5:$E$97,""),2)) | J9: =SUMIFS('Wage Detail Linked'!$O$5:$O$97,'Wage Detail Linked'!$B$5:$B$97,$A9,'Wage Detail Linked'!$C$5:$C$97,J$2,'Wage Detail Linked'!$E$5:$E$97,"") | K9: =IF(SUMIFS('Wage Detail Linked'!$O$5:$O$97,'Wage Detail Linked'!$B$5:$B$97,$A9,'Wage Detail Linked'!$C$5:$C$97,J$2,'Wage Detail Linked'!$E$5:$E$97,"")=0,IF(J9>0,ROUND(J9*90,2),0),ROUND(SUMIFS('Wage Detail Linked'!$R$5:$R$97,'Wage Detail Linked'!$B$5:$B$97,$A9,'Wage Detail Linked'!$C$5:$C$97,J$2,'Wage Detail Linked'!$E$5:$E$97,"")*J9/SUMIFS('Wage Detail Linked'!$O$5:$O$97,'Wage Detail Linked'!$B$5:$B$97,$A9,'Wage Detail Linked'!$C$5:$C$97,J$2,'Wage Detail Linked'!$E$5:$E$97,""),2)) | L9: =SUMIFS('Wage Detail Linked'!$O$5:$O$97,'Wage Detail Linked'!$B$5:$B$97,$A9,'Wage Detail Linked'!$C$5:$C$97,L$2,'Wage Detail Linked'!$E$5:$E$97,"") | M9: =IF(SUMIFS('Wage Detail Linked'!$O$5:$O$97,'Wage Detail Linked'!$B$5:$B$97,$A9,'Wage Detail Linked'!$C$5:$C$97,L$2,'Wage Detail Linked'!$E$5:$E$97,"")=0,IF(L9>0,ROUND(L9*90,2),0),ROUND(SUMIFS('Wage Detail Linked'!$R$5:$R$97,'Wage Detail Linked'!$B$5:$B$97,$A9,'Wage Detail Linked'!$C$5:$C$97,L$2,'Wage Detail Linked'!$E$5:$E$97,"")*L9/SUMIFS('Wage Detail Linked'!$O$5:$O$97,'Wage Detail Linked'!$B$5:$B$97,$A9,'Wage Detail Linked'!$C$5:$C$97,L$2,'Wage Detail Linked'!$E$5:$E$97,""),2)) | N9: =SUMIFS('Wage Detail Linked'!$O$5:$O$97,'Wage Detail Linked'!$B$5:$B$97,$A9,'Wage Detail Linked'!$C$5:$C$97,N$2,'Wage Detail Linked'!$E$5:$E$97,"") | O9: =IF(SUMIFS('Wage Detail Linked'!$O$5:$O$97,'Wage Detail Linked'!$B$5:$B$97,$A9,'Wage Detail Linked'!$C$5:$C$97,N$2,'Wage Detail Linked'!$E$5:$E$97,"")=0,IF(N9>0,ROUND(N9*90,2),0),ROUND(SUMIFS('Wage Detail Linked'!$R$5:$R$97,'Wage Detail Linked'!$B$5:$B$97,$A9,'Wage Detail Linked'!$C$5:$C$97,N$2,'Wage Detail Linked'!$E$5:$E$97,"")*N9/SUMIFS('Wage Detail Linked'!$O$5:$O$97,'Wage Detail Linked'!$B$5:$B$97,$A9,'Wage Detail Linked'!$C$5:$C$97,N$2,'Wage Detail Linked'!$E$5:$E$97,""),2)) | P9: =0 | Q9: =IF(P9>0,ROUND(P9*90,2),0) | R9: =SUM(B9,D9,F9,H9,J9,L9,N9,P9) | S9: =SUM(C9,E9,G9,I9,K9,M9,O9,Q9) | T9: 260 | U9: 260 | V9: =MAX(0,T9-U9) | W9: 1000 | X9: 1000 | Y9: =MAX(0,1600-X9) | Z9: =U9+X9 | AA9: =MAX(0,S9-Z9)
A10: John Simbarashe Mhlanga | B10: =SUMIFS('Wage Detail Linked'!$O$5:$O$97,'Wage Detail Linked'!$B$5:$B$97,$A10,'Wage Detail Linked'!$C$5:$C$97,B$2,'Wage Detail Linked'!$E$5:$E$97,"") | C10: =IF(SUMIFS('Wage Detail Linked'!$O$5:$O$97,'Wage Detail Linked'!$B$5:$B$97,$A10,'Wage Detail Linked'!$C$5:$C$97,B$2,'Wage Detail Linked'!$E$5:$E$97,"")=0,IF(B10>0,ROUND(B10*90,2),0),ROUND(SUMIFS('Wage Detail Linked'!$R$5:$R$97,'Wage Detail Linked'!$B$5:$B$97,$A10,'Wage Detail Linked'!$C$5:$C$97,B$2,'Wage Detail Linked'!$E$5:$E$97,"")*B10/SUMIFS('Wage Detail Linked'!$O$5:$O$97,'Wage Detail Linked'!$B$5:$B$97,$A10,'Wage Detail Linked'!$C$5:$C$97,B$2,'Wage Detail Linked'!$E$5:$E$97,""),2)) | D10: =SUMIFS('Wage Detail Linked'!$O$5:$O$97,'Wage Detail Linked'!$B$5:$B$97,$A10,'Wage Detail Linked'!$C$5:$C$97,D$2,'Wage Detail Linked'!$E$5:$E$97,"") | E10: =IF(SUMIFS('Wage Detail Linked'!$O$5:$O$97,'Wage Detail Linked'!$B$5:$B$97,$A10,'Wage Detail Linked'!$C$5:$C$97,D$2,'Wage Detail Linked'!$E$5:$E$97,"")=0,IF(D10>0,ROUND(D10*90,2),0),ROUND(SUMIFS('Wage Detail Linked'!$R$5:$R$97,'Wage Detail Linked'!$B$5:$B$97,$A10,'Wage Detail Linked'!$C$5:$C$97,D$2,'Wage Detail Linked'!$E$5:$E$97,"")*D10/SUMIFS('Wage Detail Linked'!$O$5:$O$97,'Wage Detail Linked'!$B$5:$B$97,$A10,'Wage Detail Linked'!$C$5:$C$97,D$2,'Wage Detail Linked'!$E$5:$E$97,""),2)) | F10: =SUMIFS('Wage Detail Linked'!$O$5:$O$97,'Wage Detail Linked'!$B$5:$B$97,$A10,'Wage Detail Linked'!$C$5:$C$97,F$2,'Wage Detail Linked'!$E$5:$E$97,"") | G10: =IF(SUMIFS('Wage Detail Linked'!$O$5:$O$97,'Wage Detail Linked'!$B$5:$B$97,$A10,'Wage Detail Linked'!$C$5:$C$97,F$2,'Wage Detail Linked'!$E$5:$E$97,"")=0,IF(F10>0,ROUND(F10*90,2),0),ROUND(SUMIFS('Wage Detail Linked'!$R$5:$R$97,'Wage Detail Linked'!$B$5:$B$97,$A10,'Wage Detail Linked'!$C$5:$C$97,F$2,'Wage Detail Linked'!$E$5:$E$97,"")*F10/SUMIFS('Wage Detail Linked'!$O$5:$O$97,'Wage Detail Linked'!$B$5:$B$97,$A10,'Wage Detail Linked'!$C$5:$C$97,F$2,'Wage Detail Linked'!$E$5:$E$97,""),2)) | H10: =SUMIFS('Wage Detail Linked'!$O$5:$O$97,'Wage Detail Linked'!$B$5:$B$97,$A10,'Wage Detail Linked'!$C$5:$C$97,H$2,'Wage Detail Linked'!$E$5:$E$97,"") | I10: =IF(SUMIFS('Wage Detail Linked'!$O$5:$O$97,'Wage Detail Linked'!$B$5:$B$97,$A10,'Wage Detail Linked'!$C$5:$C$97,H$2,'Wage Detail Linked'!$E$5:$E$97,"")=0,IF(H10>0,ROUND(H10*90,2),0),ROUND(SUMIFS('Wage Detail Linked'!$R$5:$R$97,'Wage Detail Linked'!$B$5:$B$97,$A10,'Wage Detail Linked'!$C$5:$C$97,H$2,'Wage Detail Linked'!$E$5:$E$97,"")*H10/SUMIFS('Wage Detail Linked'!$O$5:$O$97,'Wage Detail Linked'!$B$5:$B$97,$A10,'Wage Detail Linked'!$C$5:$C$97,H$2,'Wage Detail Linked'!$E$5:$E$97,""),2)) | J10: =SUMIFS('Wage Detail Linked'!$O$5:$O$97,'Wage Detail Linked'!$B$5:$B$97,$A10,'Wage Detail Linked'!$C$5:$C$97,J$2,'Wage Detail Linked'!$E$5:$E$97,"") | K10: =IF(SUMIFS('Wage Detail Linked'!$O$5:$O$97,'Wage Detail Linked'!$B$5:$B$97,$A10,'Wage Detail Linked'!$C$5:$C$97,J$2,'Wage Detail Linked'!$E$5:$E$97,"")=0,IF(J10>0,ROUND(J10*90,2),0),ROUND(SUMIFS('Wage Detail Linked'!$R$5:$R$97,'Wage Detail Linked'!$B$5:$B$97,$A10,'Wage Detail Linked'!$C$5:$C$97,J$2,'Wage Detail Linked'!$E$5:$E$97,"")*J10/SUMIFS('Wage Detail Linked'!$O$5:$O$97,'Wage Detail Linked'!$B$5:$B$97,$A10,'Wage Detail Linked'!$C$5:$C$97,J$2,'Wage Detail Linked'!$E$5:$E$97,""),2)) | L10: =SUMIFS('Wage Detail Linked'!$O$5:$O$97,'Wage Detail Linked'!$B$5:$B$97,$A10,'Wage Detail Linked'!$C$5:$C$97,L$2,'Wage Detail Linked'!$E$5:$E$97,"") | M10: =IF(SUMIFS('Wage Detail Linked'!$O$5:$O$97,'Wage Detail Linked'!$B$5:$B$97,$A10,'Wage Detail Linked'!$C$5:$C$97,L$2,'Wage Detail Linked'!$E$5:$E$97,"")=0,IF(L10>0,ROUND(L10*90,2),0),ROUND(SUMIFS('Wage Detail Linked'!$R$5:$R$97,'Wage Detail Linked'!$B$5:$B$97,$A10,'Wage Detail Linked'!$C$5:$C$97,L$2,'Wage Detail Linked'!$E$5:$E$97,"")*L10/SUMIFS('Wage Detail Linked'!$O$5:$O$97,'Wage Detail Linked'!$B$5:$B$97,$A10,'Wage Detail Linked'!$C$5:$C$97,L$2,'Wage Detail Linked'!$E$5:$E$97,""),2)) | N10: =SUMIFS('Wage Detail Linked'!$O$5:$O$97,'Wage Detail Linked'!$B$5:$B$97,$A10,'Wage Detail Linked'!$C$5:$C$97,N$2,'Wage Detail Linked'!$E$5:$E$97,"") | O10: =IF(SUMIFS('Wage Detail Linked'!$O$5:$O$97,'Wage Detail Linked'!$B$5:$B$97,$A10,'Wage Detail Linked'!$C$5:$C$97,N$2,'Wage Detail Linked'!$E$5:$E$97,"")=0,IF(N10>0,ROUND(N10*90,2),0),ROUND(SUMIFS('Wage Detail Linked'!$R$5:$R$97,'Wage Detail Linked'!$B$5:$B$97,$A10,'Wage Detail Linked'!$C$5:$C$97,N$2,'Wage Detail Linked'!$E$5:$E$97,"")*N10/SUMIFS('Wage Detail Linked'!$O$5:$O$97,'Wage Detail Linked'!$B$5:$B$97,$A10,'Wage Detail Linked'!$C$5:$C$97,N$2,'Wage Detail Linked'!$E$5:$E$97,""),2)) | P10: ='Missed Shifts'!C22 | Q10: =IF('Missed Shifts'!C22=0,IF(P10>0,ROUND(P10*90,2),0),ROUND('Missed Shifts'!D22*P10/'Missed Shifts'!C22,2)) | R10: =SUM(B10,D10,F10,H10,J10,L10,N10,P10) | S10: =SUM(C10,E10,G10,I10,K10,M10,O10,Q10) | T10: 0 | U10: 0 | V10: =MAX(0,T10-U10) | W10: 0 | X10: 0 | Y10: =MAX(0,0-X10) | Z10: =U10+X10 | AA10: =MAX(0,S10-Z10)
